Workbook

Sheet FPs
C1: =SUM(C3:C40) -> 5.25 | F1: =SUM(F5:F41) -> 3.5 | I1: =SUM(I3:I40) -> 4 | L1: 0.25 | O1: =SUM(O4:O37) -> 3.25 | R1: =SUM(R3:R41) -> 1.25 | U1: =SUM(U3:U44) -> 2.75 | X1: =SUM(X3:X41) -> 2.25 | AD1: =SUM(AD4:AD50) -> 0.75 | AG1: =SUM(AG6:AG49) -> 1.25 | AP1: =SUM(AP3:AP43) -> 1 | AV1: =SUM(AV3:AV37) -> 3.5 | AY1: =SUM(AY5:AY37) -> 4.5 | BB1: =SUM(BB3:BB47) -> 7 | BE1: =SUM(BE9:BE43) -> 2 | BK1: =SUM(BK5:BK39) -> 5.5 | BN1: =SUM(BN3:BN42) -> 2 | BQ1: =SUM(BQ3:BQ41) -> 2 | BZ1: =SUM(BZ2:BZ28) -> 7.25 | CG1: =SUM(CG4:CG40) -> 4.5 | CJ1: =SUM(CJ9:CJ42) -> 3 | CM1: =SUM(CM4:CM40) -> 2.75
A2: Name | B2: Time | D2: Name | E2: Time | G2: Name | H2: Time | J2: Name | K2: Time | M2: Name | N2: Time | P2: Name | Q2: Time | S2: Name | T2: Time | V2: Name | W2: Time | Y2: Name | Z2: Time | AB2: Name | AC2: Time | AE2: Name | AF2: Time | AH2: Name | AI2: Time | AK2: Name | AL2: Time | AN2: Name | AO2: Time | AQ2: Name | AR2: Time | AT2: Name | AU2: Time | AW2: Name | AX2: Time | AZ2: Name | BA2: Time | BC2: Name | BD2: Time | BF2: Name | BG2: Time | BI2: Name | BJ2: Time | BL2: Name | BM2: Time | BO2: Name | BP2: Time | BR2: Name | BS2: Time | BU2: Name | BV2: Time | BX2: Name | BY2: Time | CB2: Name | CC2: Time | CE2: Name | CF2: Time | CH2: Name | CI2: Time | CK2: Name | CL2: Time | CN2: Name | CO2: Time | CQ2: Name | CR2: Time
A3: Abdrahman mohamed ahmed | B3: 6/1/2026 12:02 PM | D3: Adham saad monir saad | E3: 6/1/2026 11:14 AM | G3: AHMEDMAGDY | H3: 6/2/2026 11:09 AM | I3: 1 | J3: excuse | K3: 6/1/2026 12:59 PM | M3: 14 days off | N3: 6/2/2026 10:13 PM | P3: excuse | Q3: 6/1/2026 12:24 PM | R3: 0 | S3: ALIWAEL | T3: 6/1/2026 11:58 AM | U3: 0.5 | V3: AML | W3: 6/1/2026 11:14 AM | Y3: Starting Date | Z3: 6/23/2026 1:47 PM | AB3: KAREEM | AC3: 6/1/2026 10:52 AM | AE3: MHELMY | AF3: 6/1/2026 11:13 AM | AH3: MANAR | AI3: 6/1/2026 10:51 AM | AK3: ZEINAB | AL3: 6/1/2026 10:36 AM | AN3: Eslamhesen | AO3: 6/2/2026 11:16 AM | AP3: 0.25 | AQ3: AMIRA | AR3: 6/23/2026 1:46 PM | AT3: DAWOD | AU3: 6/1/2026 11:38 AM | AV3: 0.5 | AW3: HAIDY | AX3: 6/1/2026 11:11 AM | AZ3: MOHAMEDELSAYED | BA3: 6/1/2026 12:08 PM | BB3: 1 | BC3: ANDREW | BD3: 6/1/2026 11:36 AM | BF3: excuse | BG3: 6/1/2026 12:00 PM | BI3: DAHAB | BJ3: 6/1/2026 11:14 AM | BL3: JANA | BM3: 6/1/2026 11:13 AM | BO3: MARIAM | BP3: 6/1/2026 2:01 PM | BQ3: 0.5 | BR3: NAYERA | BS3: 6/1/2026 11:02 AM | BU3: NORHAN | BV3: 6/1/2026 12:54 PM | BX3: 2 | BY3: 6/2/2026 12:20 PM | BZ3: 1 | CB3: SHAHD | CC3: 6/1/2026 1:21 PM | CE3: Ibrahimsobh | CF3: 6/1/2026 12:03 PM | CH3: Taliahany | CI3: 6/1/2026 11:56 AM | CK3: TASNEEM | CL3: 6/1/2026 11:06 AM | CN3: YARAMEDHAT | CO3: 6/1/2026 10:52 AM | CQ3: HABEBA | CR3: 6/1/2026 11:00 AM
A4: Abdrahman mohamed ahmed | B4: 6/1/2026 10:42 PM | D4: Adham saad monir saad | E4: 6/1/2026 11:14 AM | G4: AHMEDMAGDY | H4: 6/2/2026 8:59 PM | J4: AHMEDNABEL | K4: 6/1/2026 7:32 PM | M4: Ahmedmohamed | N4: 6/15/2026 11:21 AM | O4: 0.25 | P4: MAKRAM | Q4: 6/1/2026 8:18 PM | S4: ALIWAEL | T4: 6/2/2026 11:12 AM | V4: AML | W4: 6/1/2026 8:11 PM | Y4: AMALPC | Z4: 6/23/2026 1:47 PM | AB4: KAREEM | AC4: 6/1/2026 8:04 PM | AE4: MHELMY | AF4: 6/1/2026 8:02 PM | AH4: MANAR | AI4: 6/1/2026 10:51 AM | AK4: ZEINAB | AL4: 6/1/2026 7:57 PM | AN4: Eslamhesen | AO4: 6/2/2026 8:49 PM | AQ4: AMIRA | AR4: 6/23/2026 9:36 PM | AT4: DAWOD | AU4: 6/1/2026 11:38 AM | AW4: HAIDY | AX4: 6/1/2026 9:04 PM | AZ4: MOHAMEDELSAYED | BA4: 6/1/2026 8:12 PM | BC4: ANDREW | BD4: 6/1/2026 8:07 PM | BF4: Bassanti | BG4: 6/1/2026 7:05 PM | BI4: DAHAB | BJ4: 6/1/2026 8:03 PM | BL4: JANA | BM4: 6/1/2026 8:04 PM | BO4: MARIAM | BP4: 6/1/2026 8:08 PM | BR4: NAYERA | BS4: 6/1/2026 9:48 PM | BU4: NORHAN | BV4: 6/1/2026 7:00 PM | BX4: MSAEED | BY4: 6/2/2026 9:48 PM | CB4: SHAHD | CC4: 6/1/2026 8:11 PM | CE4: Ibrahimsobh | CF4: 6/1/2026 8:10 PM | CH4: Taliahany | CI4: 6/2/2026 1:05 PM | CK4: TASNEEM | CL4: 6/1/2026 8:10 PM | CN4: YARAMEDHAT | CO4: 6/1/2026 7:12 PM | CQ4: HABEBA | CR4: 6/1/2026 8:00 PM
A5: Abdrahman mohamed ahmed | B5: 6/2/2026 1:12 PM | D5: Adham saad monir saad | E5: 6/1/2026 9:36 PM | G5: AHMEDMAGDY | H5: 6/3/2026 11:24 AM | I5: 0.25 | J5: excuse | K5: 6/2/2026 12:29 PM | M5: Ahmedmohamed | N5: 6/15/2026 7:38 PM | P5: MAKRAM | Q5: 6/2/2026 11:30 AM | S5: ALIWAEL | T5: 6/2/2026 9:00 PM | V5: AML | W5: 6/2/2026 11:02 AM | Y5: AMALPC | Z5: 6/23/2026 8:37 PM | AB5: KAREEM | AC5: 6/2/2026 11:00 AM | AE5: MHELMY | AF5: 6/2/2026 11:11 AM | AH5: MANAR | AI5: 6/1/2026 7:57 PM | AK5: ZEINAB | AL5: 6/2/2026 10:37 AM | AN5: Eslamhesen | AO5: 6/3/2026 8:12 PM | AQ5: AMIRA | AR5: 6/24/2026 10:39 AM | AT5: DAWOD | AU5: 6/1/2026 8:11 PM | AW5: HAIDY | AX5: 6/2/2026 11:14 AM | AZ5: MOHAMEDELSAYED | BA5: 6/2/2026 12:47 PM | BC5: ANDREW | BD5: 6/2/2026 11:42 AM | BF5: Bassanti | BG5: 6/2/2026 11:06 AM | BI5: DAHAB | BJ5: 6/2/2026 11:24 AM | BK5: 0.25 | BL5: JANA | BM5: 6/2/2026 11:11 AM | BO5: MARIAM | BP5: 6/2/2026 11:17 AM | BQ5: 0.25 | BR5: NAYERA | BS5: 6/3/2026 11:09 AM | BT5: 2 | BU5: NORHAN | BV5: 6/2/2026 11:04 AM | BX5: MSAEED | BY5: 6/3/2026 1:02 PM | BZ5: 1 | CB5: SHAHD | CC5: 6/2/2026 10:39 AM | CE5: Ibrahimsobh | CF5: 6/2/2026 12:55 PM | CH5: Taliahany | CI5: 6/2/2026 10:12 PM | CK5: TASNEEM | CL5: 6/2/2026 11:29 AM | CM5: 0.25 | CN5: YARAMEDHAT | CO5: 6/2/2026 10:55 AM | CQ5: HABEBA | CR5: 6/2/2026 11:20 AM | CS5: 2
A6: Abdrahman mohamed ahmed | B6: 6/3/2026 12:31 PM | D6: Adham saad monir saad | E6: 6/1/2026 9:36 PM | G6: AHMEDMAGDY | H6: 6/3/2026 8:04 PM | J6: AHMEDNABEL | K6: 6/2/2026 7:47 PM | M6: excuse | N6: 6/16/2026 1:01 PM | P6: MAKRAM | Q6: 6/2/2026 9:08 PM | S6: ALIWAEL | T6: 6/3/2026 11:18 AM | U6: 0.25 | V6: AML | W6: 6/2/2026 7:59 PM | Y6: AMALPC | Z6: 6/23/2026 8:37 PM | AB6: KAREEM | AC6: 6/2/2026 8:06 PM | AE6: MHELMY | AF6: 6/2/2026 9:04 PM | AH6: MANAR | AI6: 6/2/2026 10:57 AM | AK6: ZEINAB | AL6: 6/2/2026 7:56 PM | AN6: Eslamhesen | AO6: 6/4/2026 11:16 AM | AQ6: AMIRA | AR6: 6/24/2026 8:18 PM | AT6: DAWOD | AU6: 6/2/2026 11:35 AM | AV6: 0.5 | AW6: HAIDY | AX6: 6/2/2026 8:54 PM | AZ6: MOHAMEDELSAYED | BA6: 6/2/2026 9:07 PM | BC6: ANDREW | BD6: 6/2/2026 8:48 PM | BF6: Bassanti | BG6: 6/2/2026 11:06 AM | BI6: DAHAB | BJ6: 6/2/2026 8:14 PM | BL6: JANA | BM6: 6/2/2026 9:03 PM | BO6: MARIAM | BP6: 6/2/2026 8:20 PM | BR6: NAYERA | BS6: 6/3/2026 8:16 PM | BU6: NORHAN | BV6: 6/2/2026 7:00 PM | BX6: MSAEED | BY6: 6/3/2026 11:18 PM | BZ6: 0.25 | CB6: SHAHD | CC6: 6/2/2026 8:05 PM | CE6: Ibrahimsobh | CF6: 6/2/2026 8:09 PM | CH6: Taliahany | CI6: 6/3/2026 12:21 PM | CK6: TASNEEM | CL6: 6/2/2026 8:26 PM | CN6: YARAMEDHAT | CO6: 6/2/2026 10:55 AM | CQ6: HABEBA | CR6: 6/2/2026 5:35 PM
A7: Abdrahman mohamed ahmed | B7: 6/3/2026 8:55 PM | D7: meeting | E7: 6/2/2026 12:49 PM | F7: 0 | G7: AHMEDMAGDY | H7: 6/4/2026 11:11 AM | J7: AHMEDNABEL | K7: 6/3/2026 10:45 AM | M7: Ahmedmohamed | N7: 6/16/2026 7:50 PM | P7: MAKRAM | Q7: 6/3/2026 11:21 AM | R7: 0.25 | S7: ALIWAEL | T7: 6/3/2026 8:13 PM | V7: AML | W7: 6/4/2026 10:59 AM | X7: 1 | Y7: AMALPC | Z7: 6/24/2026 10:35 AM | AB7: KAREEM | AC7: 6/3/2026 10:34 AM | AE7: MHELMY | AF7: 6/3/2026 11:15 AM | AH7: MANAR | AI7: 6/2/2026 10:58 AM | AK7: ZEINAB | AL7: 6/3/2026 11:01 AM | AN7: Eslamhesen | AO7: 6/4/2026 7:23 PM | AQ7: AMIRA | AR7: 6/25/2026 10:47 AM | AT7: DAWOD | AU7: 6/2/2026 9:09 PM | AX7: 6/3/2026 1:04 PM | AY7: 1 | AZ7: MOHAMEDELSAYED | BA7: 6/3/2026 11:37 AM | BB7: 0.5 | BC7: ANDREW | BD7: 6/3/2026 11:47 AM | BE7: 0.5 | BF7: Bassanti | BG7: 6/2/2026 7:03 PM | BI7: DAHAB | BJ7: 6/3/2026 10:57 AM | BL7: JANA | BM7: 6/3/2026 11:15 AM | BO7: MARIAM | BP7: 6/3/2026 11:15 AM | BR7: NAYERA | BS7: 6/4/2026 11:03 AM | BU7: NORHAN | BV7: 6/3/2026 11:02 AM | BX7: MSAEED | BY7: 6/7/2026 12:36 PM | CB7: SHAHD | CC7: 6/3/2026 10:40 AM | CE7: Ibrahimsobh | CF7: 6/3/2026 11:59 AM | CH7: Taliahany | CI7: 6/3/2026 8:55 PM | CK7: TASNEEM | CL7: 6/3/2026 11:58 AM | CM7: 0.5 | CN7: YARAMEDHAT | CO7: 6/2/2026 7:47 PM | CQ7: HABEBA | CR7: 6/7/2026 11:19 AM
A8: Abdrahman mohamed ahmed | B8: 6/4/2026 11:45 AM | C8: 0.5 | D8: Adham saad monir saad | E8: 6/2/2026 10:13 PM | G8: AHMEDMAGDY | H8: 6/4/2026 7:05 PM | J8: AHMEDNABEL | K8: 6/3/2026 10:45 AM | M8: Ahmedmohamed | N8: 6/17/2026 11:14 AM | P8: MAKRAM | Q8: 6/3/2026 8:20 PM | S8: ALIWAEL | T8: 6/4/2026 11:57 AM | U8: 0.5 | V8: AML | W8: 6/4/2026 6:52 PM | Y8: AMALPC | Z8: 6/25/2026 11:23 AM | AA8: 0.25 | AB8: KAREEM | AC8: 6/3/2026 8:00 PM | AE8: MHELMY | AF8: 6/3/2026 8:00 PM | AH8: MANAR | AI8: 6/2/2026 8:00 PM | AK8: ZEINAB | AL8: 6/3/2026 11:01 AM | AN8: Eslamhesen | AO8: 6/7/2026 11:19 AM | AQ8: AMIRA | AR8: 6/28/2026 10:52 AM | AT8: DAWOD | AU8: 6/3/2026 11:37 AM | AV8: 0.5 | AW8: HAIDY | AX8: 6/3/2026 8:26 PM | AZ8: MOHAMEDELSAYED | BA8: 6/3/2026 11:23 PM | BC8: ANDREW | BD8: 6/3/2026 8:13 PM | BF8: excuse | BG8: 6/3/2026 11:55 AM | BI8: 46177 | BJ8: 6/3/2026 8:09 PM | BK8: 1 | BL8: JANA | BM8: 6/3/2026 7:57 PM | BO8: MARIAM | BP8: 6/3/2026 7:56 PM | BR8: NAYERA | BS8: 6/4/2026 9:37 PM | BU8: NORHAN | BV8: 6/3/2026 7:00 PM | BX8: MSAEED | BY8: 6/7/2026 9:40 PM | CB8: SHAHD | CC8: 6/4/2026 10:42 AM | CE8: Ibrahimsobh | CF8: 6/3/2026 8:18 PM | CH8: Taliahany | CI8: 6/4/2026 11:45 AM | CK8: TASNEEM | CL8: 6/3/2026 8:03 PM | CN8: YARAMEDHAT | CO8: 6/3/2026 11:10 AM | CQ8: HABEBA | CR8: 6/7/2026 8:16 PM
A9: Abdrahman mohamed ahmed | B9: 6/7/2026 1:53 PM | D9: Adham saad monir saad | E9: 6/3/2026 11:05 AM | G9: AHMEDMAGDY | H9: 6/7/2026 11:17 AM | J9: AHMEDNABEL | K9: 6/3/2026 7:02 PM | M9: Ahmedmohamed | N9: 6/17/2026 7:47 PM | P9: meeting | Q9: 6/4/2026 12:33 PM | R9: 0 | S9: ALIWAEL | T9: 6/4/2026 7:17 PM | V9: AML | W9: 6/7/2026 8:11 PM | Y9: AMALPC | Z9: 6/25/2026 8:45 PM | AB9: KAREEM | AC9: 6/4/2026 10:57 AM | AE9: meeting | AF9: 6/4/2026 12:31 PM | AH9: MANAR | AI9: 6/3/2026 11:02 AM | AK9: ZEINAB | AL9: 6/3/2026 7:57 PM | AN9: Eslamhesen | AO9: 6/7/2026 8:13 PM | AT9: DAWOD | AU9: 6/3/2026 8:30 PM | AX9: 6/4/2026 12:54 PM | AY9: 1 | AZ9: MOHAMEDELSAYED | BA9: 6/4/2026 11:19 AM | BC9: ANDREW | BD9: 6/4/2026 11:17 AM | BF9: Bassanti | BG9: 6/3/2026 7:33 PM | BI9: DAHAB | BJ9: 6/7/2026 10:09 AM | BL9: excuse | BM9: 6/4/2026 12:27 PM | BN9: 0 | BO9: MARIAM | BP9: 6/4/2026 11:16 AM | BR9: NAYERA | BS9: 6/7/2026 11:13 AM | BU9: NORHAN | BV9: 6/4/2026 11:09 AM | BX9: MSAEED | BY9: 6/9/2026 2:15 PM | CB9: SHAHD | CC9: 6/7/2026 10:40 AM | CE9: Ibrahimsobh | CF9: 6/3/2026 8:19 PM | CH9: Taliahany | CI9: 6/4/2026 9:39 PM | CK9: TASNEEM | CL9: 6/4/2026 10:45 AM | CN9: YARAMEDHAT | CO9: 6/3/2026 7:00 PM | CQ9: HABEBA | CR9: 6/8/2026 11:13 AM
A10: Abdrahman mohamed ahmed | B10: 6/8/2026 11:11 AM | D10: Adham saad monir saad | E10: 6/3/2026 11:05 AM | G10: AHMEDMAGDY | H10: 6/7/2026 8:21 PM | J10: AHMEDNABEL | K10: 6/4/2026 10:57 AM | M10: Ahmedmohamed | N10: 6/18/2026 11:22 AM | O10: 0.25 | P10: MAKRAM | Q10: 6/4/2026 8:32 PM | S10: ALIWAEL | T10: 6/4/2026 7:18 PM | V10: AML | W10: 6/8/2026 11:13 AM | Y10: AMALPC | Z10: 6/25/2026 8:45 PM | AB10: KAREEM | AC10: 6/4/2026 7:59 PM | AE10: MHELMY | AF10: 6/4/2026 7:47 PM | AH10: MANAR | AI10: 6/3/2026 7:57 PM | AK10: ZEINAB | AL10: 6/3/2026 7:57 PM | AN10: Eslamhesen | AO10: 6/8/2026 11:07 AM | AT10: DAWOD | AU10: 6/4/2026 11:34 AM | AW10: HAIDY | AX10: 6/7/2026 11:15 AM | AZ10: MOHAMEDELSAYED | BA10: 6/4/2026 8:47 PM | BC10: ANDREW | BD10: 6/4/2026 7:05 PM | BF10: Bassanti | BG10: 6/4/2026 11:42 AM | BI10: DAHAB | BJ10: 6/7/2026 8:02 PM | BL10: JANA | BM10: 6/4/2026 7:42 PM | BO10: MARIAM | BP10: 6/4/2026 7:10 PM | BR10: NAYERA | BS10: 6/7/2026 6:59 PM | BU10: NORHAN | BV10: 6/4/2026 6:56 PM | BX10: MSAEED | BY10: 6/9/2026 8:56 PM | CB10: SHAHD | CC10: 6/8/2026 10:50 AM | CE10: Ibrahimsobh | CF10: 6/4/2026 11:53 AM | CH10: Taliahany | CI10: 6/7/2026 12:52 PM | CK10: TASNEEM | CL10: 6/4/2026 7:04 PM | CN10: YARAMEDHAT | CO10: 6/4/2026 10:49 AM | CQ10: HABEBA | CR10: 6/8/2026 7:07 PM
A11: Abdrahman mohamed ahmed | B11: 6/9/2026 11:13 AM | D11: Adham saad monir saad | E11: 6/3/2026 8:55 PM | G11: AHMEDMAGDY | H11: 6/8/2026 11:14 AM | J11: AHMEDNABEL | K11: 6/4/2026 7:06 PM | M11: Ahmedmohamed | N11: 6/18/2026 7:46 PM | P11: MAKRAM | Q11: 6/7/2026 11:12 AM | S11: ALIWAEL | T11: 6/7/2026 11:08 AM | V11: AML | W11: 6/8/2026 8:05 PM | Y11: AMALPC | Z11: 6/28/2026 10:35 AM | AB11: KAREEM | AC11: 6/7/2026 12:37 PM | AE11: MHELMY | AF11: 6/7/2026 11:10 AM | AH11: MANAR | AI11: 6/4/2026 10:59 AM | AK11: ZEINAB | AL11: 6/4/2026 10:38 AM | AN11: Eslamhesen | AO11: 6/8/2026 8:16 PM | AT11: DAWOD | AU11: 6/4/2026 7:25 PM | AW11: HAIDY | AX11: 6/7/2026 8:38 PM | AZ11: MOHAMEDELSAYED | BA11: 6/7/2026 11:40 AM | BC11: excuse | BD11: 6/7/2026 12:56 PM | BF11: Bassanti | BG11: 6/4/2026 6:54 PM | BI11: DAHAB | BJ11: 6/8/2026 12:31 PM | BL11: JANA | BM11: 6/7/2026 11:10 AM | BO11: MARIAM | BP11: 6/7/2026 11:07 AM | BR11: NAYERA | BS11: 6/8/2026 11:26 AM | BU11: NORHAN | BV11: 6/7/2026 12:35 PM | BX11: MSAEED | BY11: 6/10/2026 1:56 PM | CB11: SHAHD | CC11: 6/8/2026 8:12 PM | CE11: Ibrahimsobh | CF11: 6/4/2026 7:11 PM | CH11: Taliahany | CI11: 6/7/2026 8:20 PM | CK11: TASNEEM | CL11: 6/7/2026 12:51 PM | CN11: YARAMEDHAT | CO11: 6/4/2026 7:05 PM | CQ11: HABEBA | CR11: 6/9/2026 11:11 AM
A12: Abdrahman mohamed ahmed | B12: 6/9/2026 9:09 PM | D12: Adham saad monir saad | E12: 6/3/2026 8:56 PM | G12: AHMEDMAGDY | H12: 6/8/2026 5:54 PM | J12: AHMEDNABEL | K12: 6/7/2026 11:06 AM | M12: Saturday | N12: 6/20/2026 1:20 PM | P12: MAKRAM | Q12: 6/7/2026 8:06 PM | S12: ALIWAEL | T12: 6/7/2026 8:17 PM | V12: AML | W12: 6/9/2026 7:57 PM | X12: 0.25 | AB12: KAREEM | AC12: 6/7/2026 8:03 PM | AE12: MHELMY | AF12: 6/7/2026 11:14 AM | AH12: MANAR | AI12: 6/4/2026 7:17 PM | AK12: ZEINAB | AL12: 6/4/2026 6:05 PM | AN12: Eslamhesen | AO12: 6/9/2026 11:32 AM | AT12: DAWOD | AU12: 6/7/2026 11:16 AM | AW12: HAIDY | AX12: 6/8/2026 12:56 PM | AY12: 0 | AZ12: MOHAMEDELSAYED | BA12: 6/7/2026 8:20 PM | BC12: ANDREW | BD12: 6/7/2026 8:13 PM | BF12: Bassanti | BG12: 6/7/2026 11:12 AM | BI12: DAHAB | BJ12: 6/8/2026 8:09 PM | BL12: JANA | BM12: 6/7/2026 8:08 PM | BO12: MARIAM | BP12: 6/7/2026 8:03 PM | BR12: NAYERA | BS12: 6/8/2026 7:02 PM | BU12: NORHAN | BV12: 6/7/2026 7:03 PM | BX12: MSAEED | BY12: 6/10/2026 9:42 PM | CB12: SHAHD | CC12: 6/9/2026 10:50 AM | CE12: Ibrahimsobh | CF12: 6/7/2026 1:16 PM | CH12: Taliahany | CI12: 6/8/2026 11:11 AM | CK12: TASNEEM | CL12: 6/7/2026 8:23 PM | CN12: YARAMEDHAT | CO12: 6/7/2026 10:52 AM | CQ12: HABEBA | CR12: 6/9/2026 8:22 PM
A13: Abdrahman mohamed ahmed | B13: 6/10/2026 1:23 PM | D13: excuse | E13: 6/4/2026 12:20 PM | F13: 0 | G13: AHMEDMAGDY | H13: 6/9/2026 11:13 AM | J13: AHMEDNABEL | K13: 6/7/2026 7:37 PM | M13: Ahmedmohamed | N13: 6/20/2026 8:33 PM | P13: MAKRAM | Q13: 6/8/2026 11:45 AM | R13: ? | S13: ALIWAEL | T13: 6/8/2026 3:47 PM | U13: ? | V13: AML | W13: 6/10/2026 10:56 AM | AB13: KAREEM | AC13: 6/8/2026 11:01 AM | AE13: MHELMY | AF13: 6/7/2026 8:09 PM | AH13: MANAR | AI13: 6/7/2026 11:04 AM | AK13: ZEINAB | AL13: 6/7/2026 10:36 AM | AN13: Eslamhesen | AO13: 6/9/2026 7:59 PM | AT13: DAWOD | AU13: 6/7/2026 8:17 PM | AW13: HAIDY | AX13: 6/8/2026 8:07 PM | AZ13: MOHAMEDELSAYED | BA13: 6/8/2026 11:45 AM | BC13: ANDREW | BD13: 6/9/2026 11:32 AM | BF13: Bassanti | BG13: 6/7/2026 7:15 PM | BI13: DAHAB | BJ13: 6/9/2026 11:26 AM | BL13: JANA | BM13: 6/8/2026 11:23 AM | BO13: MARIAM | BP13: 6/8/2026 11:02 AM | BR13: NAYERA | BS13: 6/9/2026 11:14 AM | BU13: NORHAN | BV13: 6/9/2026 10:48 AM | BX13: MSAEED | BY13: 6/11/2026 4:35 PM | CB13: SHAHD | CC13: 6/9/2026 8:14 PM | CE13: Ibrahimsobh | CF13: 6/7/2026 8:17 PM | CH13: Taliahany | CI13: 6/8/2026 7:44 PM | CK13: TASNEEM | CL13: 6/8/2026 11:19 AM | CN13: YARAMEDHAT | CO13: 6/7/2026 7:03 PM | CQ13: HABEBA | CR13: 6/10/2026 11:28 AM
A14: Abdrahman mohamed ahmed | B14: 6/10/2026 9:46 PM | D14: Adham saad monir saad | E14: 6/4/2026 9:36 PM | G14: AHMEDMAGDY | H14: 6/9/2026 7:59 PM | J14: AHMEDNABEL | K14: 6/8/2026 11:56 AM | N14: 6/21/2026 12:10 PM | O14: 1 | P14: MAKRAM | Q14: 6/8/2026 8:15 PM | S14: ALIWAEL | T14: 6/8/2026 6:03 PM | V14: AML | W14: 6/10/2026 7:57 PM | AB14: KAREEM | AC14: 6/8/2026 8:11 PM | AE14: MHELMY | AF14: 6/8/2026 11:23 AM | AH14: MANAR | AI14: 6/7/2026 8:03 PM | AK14: ZEINAB | AL14: 6/7/2026 4:30 PM | AN14: Eslamhesen | AO14: 6/10/2026 11:00 AM | AT14: DAWOD | AU14: 6/8/2026 11:27 AM | AW14: HAIDY | AX14: 6/8/2026 8:15 PM | AZ14: MOHAMEDELSAYED | BA14: 6/8/2026 8:49 PM | BC14: ANDREW | BD14: 6/9/2026 8:00 PM | BF14: Bassanti | BG14: 6/9/2026 11:11 AM | BI14: DAHAB | BJ14: 6/9/2026 8:14 PM | BL14: JANA | BM14: 6/8/2026 8:12 PM | BO14: MARIAM | BP14: 6/8/2026 7:05 PM | BR14: NAYERA | BS14: 6/9/2026 7:01 PM | BU14: NORHAN | BV14: 6/9/2026 7:00 PM | BX14: MSAEED | BY14: 6/11/2026 8:47 PM | CB14: SHAHD | CC14: 6/10/2026 10:53 AM | CE14: Ibrahimsobh | CF14: 6/8/2026 10:55 AM | CH14: Taliahany | CI14: 6/9/2026 11:14 AM | CK14: TASNEEM | CL14: 6/10/2026 11:12 AM | CN14: YARAMEDHAT | CO14: 6/8/2026 10:49 AM | CQ14: HABEBA | CR14: 6/10/2026 7:58 PM
A15: Abdrahman mohamed ahmed | B15: 6/11/2026 10:17 PM | D15: Adham saad monir saad | E15: 6/4/2026 9:39 PM | G15: AHMEDMAGDY | H15: 6/10/2026 11:16 AM | J15: AHMEDNABEL | K15: 6/8/2026 11:57 AM | M15: Ahmedmohamed | N15: 6/21/2026 7:57 PM | P15: MAKRAM | Q15: 6/9/2026 11:11 AM | S15: ALIWAEL | T15: 6/8/2026 6:03 PM | V15: AML | W15: 6/11/2026 11:04 AM | AB15: KAREEM | AC15: 6/9/2026 11:10 AM | AE15: MHELMY | AF15: 6/8/2026 8:23 PM | AH15: MANAR | AI15: 6/8/2026 10:45 AM | AK15: ZEINAB | AL15: 6/9/2026 10:16 AM | AN15: Eslamhesen | AO15: 6/11/2026 11:22 AM | AT15: DAWOD | AU15: 6/8/2026 8:49 PM | AW15: HAIDY | AX15: 6/9/2026 10:55 AM | AZ15: MOHAMEDELSAYED | BA15: 6/9/2026 11:56 AM | BC15: ANDREW | BD15: 6/10/2026 11:31 AM | BF15: Bassanti | BG15: 6/9/2026 7:09 PM | BI15: DAHAB | BJ15: 6/10/2026 11:15 AM | BL15: JANA | BM15: 6/9/2026 12:04 PM | BO15: MARIAM | BP15: 6/10/2026 11:20 AM | BR15: NAYERA | BS15: 6/10/2026 11:21 AM | BU15: NORHAN | BV15: 6/10/2026 11:06 AM | BX15: MSAEED | BY15: 6/14/2026 9:28 PM | CB15: SHAHD | CC15: 6/10/2026 8:06 PM | CE15: Ibrahimsobh | CF15: 6/8/2026 8:15 PM | CH15: Taliahany | CI15: 6/9/2026 7:22 PM | CK15: TASNEEM | CL15: 6/10/2026 7:57 PM | CN15: YARAMEDHAT | CO15: 6/8/2026 7:02 PM | CQ15: HABEBA | CR15: 6/11/2026 11:16 AM
A16: Saturday | B16: Saturday 2:56:00 PM | D16: Adham saad monir saad | E16: Saturday 12:59 PM | G16: AHMEDMAGDY | H16: 6/10/2026 7:59 PM | J16: AHMEDNABEL | K16: 6/8/2026 7:02 PM | M16: Ahmedmohamed | N16: 6/21/2026 7:57 PM | P16: MAKRAM | Q16: 6/9/2026 8:12 PM | S16: ALIWAEL | T16: 6/9/2026 1:23 PM | U16: ? | V16: AML | W16: 6/11/2026 7:55 PM | AB16: KAREEM | AC16: 6/9/2026 7:58 PM | AE16: MHELMY | AF16: 6/9/2026 12:04 PM | AH16: MANAR | AI16: 6/8/2026 10:48 AM | AK16: 1 | AL16: 46181 | AN16: Eslamhesen | AO16: 6/11/2026 7:15 PM | AT16: excuse | AU16: 6/9/2026 12:55 PM | AW16: HAIDY | AX16: 6/9/2026 8:23 PM | AZ16: MOHAMEDELSAYED | BA16: 6/9/2026 8:25 PM | BC16: ANDREW | BD16: 6/10/2026 8:18 PM | BF16: Bassanti | BG16: 6/10/2026 11:40 AM | BI16: DAHAB | BJ16: 6/10/2026 7:51 PM | BL16: JANA | BM16: 6/9/2026 8:03 PM | BO16: MARIAM | BP16: 6/10/2026 7:57 PM | BR16: NAYERA | BS16: 6/10/2026 7:09 PM | BU16: NORHAN | BV16: 6/10/2026 7:00 PM | BX16: MSAEED | BY16: 6/16/2026 12:07 PM | BZ16: 1 | CB16: SHAHD | CC16: 6/11/2026 10:49 AM | CE16: Ibrahimsobh | CF16: 6/10/2026 12:38 PM | CH16: Taliahany | CI16: 6/10/2026 11:21 AM | CK16: TASNEEM | CL16: 6/14/2026 11:36 AM | CM16: 0.5 | CN16: YARAMEDHAT | CO16: 6/9/2026 10:48 AM | CQ16: HABEBA | CR16: 6/11/2026 6:01 PM
A17: excuse | B17: 6/14/2026 12:17 PM | C17: 0 | D17: Adham saad monir saad | E17: 6/14/2026 11:32 AM | F17: 0.5 | G17: AHMEDMAGDY | H17: 6/11/2026 11:09 AM | J17: meeting | K17: 6/9/2026 12:02 PM | M17: Ahmedmohamed | N17: 6/22/2026 3:38 PM | P17: MAKRAM | Q17: 6/10/2026 12:13 PM | R17: ? | S17: ALIWAEL | T17: 6/9/2026 7:59 PM | V17: AML | W17: Saturday 12:00 PM | AB17: KAREEM | AC17: 6/10/2026 11:15 AM | AE17: MHELMY | AF17: 6/9/2026 8:03 PM | AH17: MANAR | AI17: 6/8/2026 8:13 PM | AK17: ZEINAB | AL17: 6/9/2026 7:56 PM | AN17: Eslamhesen | AO17: 6/13/2026 12:09 PM | AT17: DAWOD | AU17: 6/9/2026 8:18 PM | AW17: HAIDY | AX17: 6/10/2026 11:15 AM | AZ17: MOHAMEDELSAYED | BA17: 6/10/2026 11:40 AM | BC17: ANDREW | BD17: 6/11/2026 12:11 PM | BF17: Bassanti | BG17: 6/10/2026 8:04 PM | BI17: meeting | BJ17: 6/11/2026 1:24 PM | BL17: JANA | BM17: 6/10/2026 11:23 AM | BO17: MARIAM | BP17: 6/11/2026 11:40 AM | BR17: NAYERA | BS17: 6/10/2026 7:09 PM | BU17: NORHAN | BV17: 6/11/2026 11:04 AM | BX17: MSAEED | BY17: 6/16/2026 10:23 PM | CB17: SHAHD | CC17: 6/11/2026 8:03 PM | CE17: Ibrahimsobh | CF17: 6/10/2026 6:08 PM | CH17: Taliahany | CI17: 6/10/2026 9:46 PM | CK17: TASNEEM | CL17: 6/14/2026 7:38 PM | CN17: YARAMEDHAT | CO17: 6/9/2026 7:00 PM | CR17: 6/13/2026 12:14 PM
A18: Abdrahman mohamed ahmed | B18: 6/15/2026 11:18 AM | C18: 0.25 | D18: Adham saad monir saad | E18: 6/14/2026 8:24 PM | G18: AHMEDMAGDY | H18: 6/11/2026 6:58 PM | J18: AHMEDNABEL | K18: 6/9/2026 7:19 PM | M18: Ahmedmohamed | N18: 6/22/2026 8:36 PM | P18: MAKRAM | Q18: 6/10/2026 8:06 PM | S18: ALIWAEL | T18: 6/10/2026 11:22 AM | U18: ? | V18: AML | W18: Saturday 6:59 PM | AB18: KAREEM | AC18: 6/10/2026 7:57 PM | AE18: MHELMY | AF18: 6/10/2026 11:25 AM | AH18: MANAR | AI18: 6/9/2026 10:53 AM | AK18: ZEINAB | AL18: 6/10/2026 10:25 AM | AN18: Eslamhesen | AO18: 6/13/2026 6:59 PM | AT18: DAWOD | AU18: 6/10/2026 10:56 AM | AW18: HAIDY | AX18: 6/10/2026 8:05 PM | AZ18: MOHAMEDELSAYED | BA18: 6/10/2026 8:12 PM | BC18: ANDREW | BD18: 6/11/2026 7:15 PM | BF18: Bassanti | BG18: 6/11/2026 11:00 AM | BI18: DAHAB | BJ18: 6/11/2026 8:02 PM | BK18: 3 | BL18: JANA | BM18: 6/10/2026 8:03 PM | BO18: MARIAM | BP18: 6/11/2026 5:55 PM | BR18: NAYERA | BS18: 6/11/2026 11:00 AM | BU18: NORHAN | BV18: 6/14/2026 11:06 AM | BX18: MSAEED | BY18: 6/17/2026 12:22 PM | BZ18: 1 | CB18: SHAHD | CC18: 6/13/2026 11:52 AM | CE18: Ibrahimsobh | CF18: 6/10/2026 6:12 PM | CH18: Taliahany | CI18: 6/11/2026 10:17 PM | CK18: excuse | CL18: 6/21/2026 11:32 AM | CM18: 0 | CN18: YARAMEDHAT | CO18: 6/10/2026 10:53 AM | CQ18: HABEBA | CR18: 6/13/2026 6:55 PM
A19: Abdrahman mohamed ahmed | B19: 6/16/2026 12:57 PM | C19: 1 | D19: Adham saad monir saad | E19: 6/15/2026 11:29 AM | F19: 0.25 | G19: AHMEDMAGDY | H19: Saturday 12:17 PM | J19: AHMEDNABEL | K19: 6/10/2026 11:04 AM | M19: Ahmedmohamed | N19: 6/23/2026 11:39 AM | O19: 0.5 | P19: MAKRAM | Q19: 6/11/2026 11:08 AM | S19: ALIWAEL | T19: 6/10/2026 8:19 PM | V19: AML | W19: 6/14/2026 11:00 AM | AB19: KAREEM | AC19: 6/11/2026 11:00 AM | AE19: MHELMY | AF19: 6/10/2026 7:58 PM | AH19: MANAR | AI19: 6/9/2026 7:55 PM | AK19: ZEINAB | AL19: 6/10/2026 7:57 PM | AN19: Eslamhesen | AO19: 6/14/2026 11:05 AM | AT19: DAWOD | AU19: 6/10/2026 7:56 PM | AW19: HAIDY | AX19: 6/11/2026 12:48 PM | AY19: 0 | AZ19: MOHAMEDELSAYED | BA19: 6/10/2026 8:19 PM | BC19: ANDREW | BD19: 6/13/2026 12:46 PM | BF19: Bassanti | BG19: 6/11/2026 7:43 PM | BI19: DAHAB | BJ19: 6/17/2026 11:02 AM | BM19: 6/15/2026 11:37 AM | BN19: 0.5 | BO19: MARIAM | BP19: 6/15/2026 12:39 PM | BR19: NAYERA | BS19: 6/11/2026 7:06 PM | BU19: NORHAN | BV19: 6/14/2026 11:09 AM | BX19: MSAEED | BY19: 6/17/2026 11:12 PM | CB19: SHAHD | CC19: 6/13/2026 6:59 PM | CE19: Ibrahimsobh | CF19: 6/21/2026 1:10 PM | CG19: 1 | CH19: Taliahany | CI19: 6/13/2026 7:03 PM | CK19: TASNEEM | CL19: 6/21/2026 8:30 PM | CN19: YARAMEDHAT | CO19: 6/10/2026 7:00 PM | CQ19: HABEBA | CR19: 6/14/2026 11:11 AM
A20: Abdrahman mohamed ahmed | B20: 6/16/2026 10:25 PM | D20: Adham saad monir saad | E20: 6/15/2026 7:37 PM | G20: AHMEDMAGDY | H20: 46187 | I20: 1 | J20: AHMEDNABEL | K20: 6/10/2026 11:05 AM | M20: Ahmedmohamed | N20: 6/23/2026 9:08 PM | P20: MAKRAM | Q20: Saturday 7:05 PM | S20: meeting | T20: 6/11/2026 1:44 PM | V20: AML | W20: 6/15/2026 10:59 AM | AB20: KAREEM | AC20: 6/11/2026 7:00 PM | AE20: MHELMY | AF20: 6/11/2026 11:08 AM | AH20: MANAR | AI20: 6/10/2026 10:48 AM | AK20: ZEINAB | AL20: 6/11/2026 10:47 AM | AN20: Eslamhesen | AO20: 6/14/2026 7:57 PM | AT20: DAWOD | AU20: 6/13/2026 11:56 AM | AV20: 0.5 | AW20: HAIDY | AX20: 6/11/2026 7:24 PM | AZ20: MOHAMEDELSAYED | BA20: 6/11/2026 12:30 PM | BC20: ANDREW | BD20: 6/13/2026 6:56 PM | BF20: Bassanti | BG20: 6/15/2026 11:22 AM | BI20: DAHAB | BJ20: 6/17/2026 8:04 PM | BL20: JANA | BM20: 6/15/2026 7:52 PM | BO20: MARIAM | BP20: 6/15/2026 7:38 PM | BR20: NAYERA | BS20: 6/14/2026 11:00 AM | BU20: NORHAN | BV20: 6/14/2026 7:00 PM | BX20: MSAEED | BY20: 6/18/2026 2:52 PM | BZ20: 1 | CB20: SHAHD | CC20: 6/14/2026 10:56 AM | CE20: Ibrahimsobh | CF20: 6/21/2026 7:44 PM | CH20: Taliahany | CI20: 6/14/2026 1:45 PM | CJ20: 1 | CK20: excuse | CL20: 6/22/2026 1:14 PM | CM20: 0.25 | CN20: YARAMEDHAT | CO20: 6/11/2026 10:47 AM | CQ20: HABEBA | CR20: 6/15/2026 10:59 AM
A21: Abdrahman mohamed ahmed | B21: 6/17/2026 11:05 AM | D21: Adham saad monir saad | E21: 6/16/2026 11:29 AM | F21: 0.25 | G21: AHMEDMAGDY | H21: 6/15/2026 11:12 AM | J21: AHMEDNABEL | K21: 6/10/2026 5:46 PM | M21: Ahmedmohamed | N21: 6/24/2026 11:54 AM | O21: 0.5 | P21: excuse | Q21: 6/14/2026 12:20 PM | S21: ALIWAEL | T21: Saturday 1:28 PM | V21: AML | W21: 6/15/2026 7:33 PM | AB21: KAREEM | AC21: 6/14/2026 11:08 AM | AE21: MHELMY | AF21: 6/11/2026 5:02 PM | AH21: MANAR | AI21: 6/10/2026 7:53 PM | AK21: ZEINAB | AL21: 6/11/2026 5:00 PM | AN21: Eslamhesen | AO21: 6/15/2026 10:58 AM | AT21: DAWOD | AU21: 6/14/2026 11:17 AM | AW21: HAIDY | AX21: 6/13/2026 2:32 PM | AY21: 1 | AZ21: MOHAMEDELSAYED | BA21: 6/11/2026 8:17 PM | BC21: ANDREW | BD21: 6/14/2026 11:40 AM | BF21: Bassanti | BG21: 6/15/2026 4:23 PM | BI21: DAHAB | BJ21: 6/18/2026 10:16 AM | BL21: excuse | BM21: 6/16/2026 11:22 AM | BO21: meeting | BP21: 6/21/2026 2:16 PM | BR21: NAYERA | BS21: 6/14/2026 7:00 PM | BU21: NORHAN | BV21: 6/15/2026 10:59 AM | BX21: MSAEED | BY21: 6/21/2026 3:29 PM | BZ21: 1 | CB21: SHAHD | CC21: 6/14/2026 8:10 PM | CE21: Ibrahimsobh | CF21: 6/21/2026 7:47 PM | CH21: Taliahany | CI21: 6/14/2026 4:43 PM | CK21: TASNEEM | CL21: 6/22/2026 8:24 PM | CN21: YARAMEDHAT | CO21: 6/11/2026 7:09 PM | CQ21: HABEBA | CR21: 6/15/2026 7:43 PM
A22: excuse | B22: 6/18/2026 1:02 PM | C22: 0 | D22: Adham saad monir saad | E22: 6/16/2026 7:50 PM | G22: AHMEDMAGDY | H22: 46189 | I22: 1 | J22: AHMEDNABEL | K22: 6/11/2026 11:08 AM | M22: Ahmedmohamed | N22: 6/24/2026 8:16 PM | P22: MAKRAM | Q22: 6/14/2026 8:21 PM | S22: ALIWAEL | T22: Saturday 6:00 PM | V22: AML | W22: 6/16/2026 11:12 AM | AB22: 1 | AC22: 46188 | AE22: MHELMY | AF22: 6/13/2026 12:40 PM | AH22: MANAR | AI22: 6/11/2026 10:55 AM | AK22: ZEINAB | AL22: 6/15/2026 7:34 PM | AN22: Eslamhesen | AO22: 6/16/2026 11:12 AM | AT22: DAWOD | AU22: 6/15/2026 11:46 AM | AW22: HAIDY | AX22: 6/13/2026 6:28 PM | AZ22: excuse | BA22: 6/13/2026 12:45 PM | BB22: 0 | BC22: ANDREW | BD22: 6/14/2026 7:57 PM | BF22: Bassanti | BG22: 6/21/2026 11:00 AM | BI22: DAHAB | BJ22: 6/18/2026 7:16 PM | BL22: JANA | BM22: 6/16/2026 7:57 PM | BO22: MARIAM | BP22: 6/21/2026 8:24 PM | BR22: NAYERA | BS22: 6/15/2026 11:10 AM | BU22: NORHAN | BV22: 6/15/2026 7:00 PM | BX22: MSAEED | BY22: 6/21/2026 9:15 PM | CB22: SHAHD | CC22: 6/15/2026 10:53 AM | CE22: Ibrahimsobh | CF22: 6/23/2026 10:56 AM | CH22: Taliahany | CI22: 6/15/2026 11:18 AM | CK22: exception from selim | CL22: 6/23/2026 2:50 PM | CM22: 0.5 | CN22: YARAMEDHAT | CO22: 6/14/2026 10:48 AM | CQ22: HABEBA | CR22: 6/16/2026 11:12 AM
A23: Abdrahman mohamed ahmed | B23: 6/18/2026 9:32 PM | D23: Adham saad monir saad | E23: 6/17/2026 11:37 AM | F23: 0.5 | G23: AHMEDMAGDY | H23: 6/17/2026 11:12 AM | J23: AHMEDNABEL | K23: 6/11/2026 7:07 PM | M23: Ahmedmohamed | N23: 6/25/2026 11:58 AM | O23: 0.5 | P23: MAKRAM | Q23: 6/15/2026 11:32 AM | R23: 0.5 | S23: excuse | T23: 6/14/2026 12:04 PM | U23: 0 | V23: AML | W23: 6/17/2026 11:02 AM | AB23: KAREEM | AC23: 6/16/2026 11:12 AM | AE23: MHELMY | AF23: 6/13/2026 6:55 PM | AH23: MANAR | AI23: 6/11/2026 7:09 PM | AK23: meeting | AL23: 6/16/2026 12:19 PM | AN23: meeting | AO23: 6/17/2026 11:21 AM | AT23: DAWOD | AU23: 6/16/2026 11:18 AM | AW23: HAIDY | AX23: 6/14/2026 11:02 AM | AZ23: MOHAMEDELSAYED | BA23: 6/14/2026 12:04 PM | BB23: 1 | BD23: 6/15/2026 11:36 AM | BE23: 0.5 | BF23: Bassanti | BG23: 6/21/2026 6:58 PM | BI23: DAHAB | BJ23: 6/20/2026 12:57 PM | BL23: JANA | BM23: 6/17/2026 11:01 AM | BO23: meeting | BP23: 6/22/2026 1:03 PM | BR23: NAYERA | BS23: 6/15/2026 7:03 PM | BU23: NORHAN | BV23: 6/17/2026 10:37 AM | BX23: meeting informed by samaher | BY23: 6/22/2026 6:48 PM | CB23: SHAHD | CC23: 6/15/2026 10:53 AM | CE23: Ibrahimsobh | CF23: 6/23/2026 9:14 PM | CH23: Taliahany | CI23: 6/15/2026 8:26 PM | CK23: TASNEEM | CL23: 6/23/2026 8:49 PM | CN23: YARAMEDHAT | CO23: 6/14/2026 7:00 PM | CQ23: HABEBA | CR23: 6/17/2026 11:08 AM
A24: Saturday | B24: 6/20/2026 2:14 PM | D24: Adham saad monir saad | E24: 6/17/2026 7:51 PM | G24: AHMEDMAGDY | H24: 6/17/2026 7:59 PM | J24: AHMEDNABEL | K24: 6/11/2026 7:08 PM | M24: Ahmedmohamed | N24: 6/25/2026 8:41 PM | P24: MAKRAM | Q24: 6/15/2026 7:44 PM | S24: ALIWAEL | T24: 6/14/2026 9:02 PM | V24: AML | W24: 6/17/2026 6:24 PM | AB24: KAREEM | AC24: 6/17/2026 11:11 AM | AE24: excuse | AF24: 6/14/2026 11:23 AM | AG24: 0 | AH24: MANAR | AI24: 6/13/2026 11:39 AM | AK24: ZEINAB | AL24: 6/16/2026 7:57 PM | AN24: Eslamhesen | AO24: 6/17/2026 7:31 PM | AT24: DAWOD | AU24: 6/16/2026 8:08 PM | AW24: HAIDY | AX24: 6/15/2026 11:32 AM | AY24: 0.5 | AZ24: MOHAMEDELSAYED | BA24: 6/14/2026 8:27 PM | BC24: ANDREW | BD24: 6/15/2026 7:43 PM | BF24: Bassanti | BG24: 6/22/2026 11:05 AM | BI24: DAHAB | BJ24: 6/20/2026 6:56 PM | BL24: JANA | BM24: 6/17/2026 8:08 PM | BO24: MARIAM | BP24: 6/22/2026 8:21 PM | BR24: excuse | BS24: 6/16/2026 11:39 AM | BT24: 0 | BU24: NORHAN | BV24: 6/17/2026 10:56 AM | BX24: meeting informed by samaher | BY24: 46198.875 | CB24: SHAHD | CC24: 6/15/2026 7:48 PM | CE24: Ibrahimsobh | CF24: 6/24/2026 11:49 AM | CG24: 0.5 | CH24: Taliahany | CI24: 6/16/2026 11:14 AM | CK24: TASNEEM | CL24: 6/24/2026 11:28 AM | CM24: 0.25 | CN24: YARAMEDHAT | CO24: 6/15/2026 10:45 AM | CQ24: HABEBA | CR24: 6/17/2026 3:50 PM
A25: Abdrahman mohamed ahmed | B25: 6/20/2026 8:29 PM | D25: Adham saad monir saad | E25: 6/18/2026 11:59 AM | F25: 0.5 | G25: excuse | H25: 6/18/2026 11:22 AM | I25: 0.25 | J25: meeting | K25: 6/14/2026 2:34 PM | N25: 46201 | P25: meeting | Q25: 6/16/2026 12:22 PM | S25: excuse | T25: 6/15/2026 12:40 PM | U25: 0 | V25: AML | W25: 6/18/2026 10:47 AM | AB25: KAREEM | AC25: 6/17/2026 8:00 PM | AE25: MHELMY | AF25: 6/14/2026 8:07 PM | AH25: MANAR | AI25: 6/13/2026 11:39 AM | AK25: ZEINAB | AL25: 6/17/2026 11:11 AM | AN25: Eslamhesen | AO25: 6/18/2026 11:22 AM | AP25: 0.25 | AT25: excuse | AU25: 6/17/2026 12:27 PM | AW25: HAIDY | AX25: 6/15/2026 7:55 PM | AZ25: excuse | BA25: 6/15/2026 12:32 PM | BB25: 0 | BC25: ANDREW | BD25: 6/16/2026 1:03 PM | BF25: Bassanti | BG25: 6/23/2026 11:45 AM | BI25: DAHAB | BJ25: 6/20/2026 7:07 PM | BL25: JANA | BM25: 6/18/2026 11:25 AM | BN25: 0.25 | BO25: excuse | BP25: 6/23/2026 12:01 PM | BQ25: 0 | BR25: NAYERA | BS25: 6/17/2026 11:05 AM | BU25: NORHAN | BV25: 6/17/2026 3:03 PM | BX25: MSAEED | BY25: 6/24/2026 1:33 PM | BZ25: 1 | CB25: SHAHD | CC25: 6/16/2026 11:11 AM | CE25: Ibrahimsobh | CF25: 6/24/2026 8:45 PM | CH25: Taliahany | CI25: 6/16/2026 10:24 PM | CK25: TASNEEM | CL25: 6/24/2026 8:06 PM | CN25: YARAMEDHAT | CO25: 6/15/2026 10:45 AM | CQ25: HABEBA | CR25: 6/18/2026 11:11 AM
A26: Abdrahman mohamed ahmed | B26: 6/21/2026 12:22 PM | C26: 1 | D26: Adham saad monir saad | E26: 6/18/2026 7:47 PM | G26: AHMEDMAGDY | H26: 6/18/2026 7:04 PM | J26: AHMEDNABEL | K26: 6/15/2026 11:18 AM | L26: 0.25 | N26: 46202 | P26: meeting | Q26: 6/17/2026 1:25 PM | R26: 0 | S26: meeting | T26: 6/16/2026 12:19 PM | U26: 0 | V26: AML | W26: 6/18/2026 7:14 PM | AB26: excuse | AC26: 6/18/2026 11:23 AM | AD26: 0 | AE26: excuse | AF26: 6/15/2026 11:37 AM | AG26: 0 | AH26: MANAR | AI26: 6/13/2026 6:59 PM | AK26: ZEINAB | AL26: 6/17/2026 8:15 PM | AN26: Eslamhesen | AO26: 6/18/2026 7:47 PM | AT26: DAWOD | AU26: 6/18/2026 11:56 AM | AW26: HAIDY | AX26: 6/16/2026 11:11 AM | AZ26: MOHAMEDELSAYED | BA26: 6/15/2026 7:48 PM | BC26: excuse | BD26: 6/16/2026 8:17 PM | BF26: Bassanti | BG26: 6/23/2026 6:13 PM | BI26: excuse | BJ26: 6/21/2026 11:34 AM | BK26: 0 | BL26: JANA | BM26: 6/18/2026 7:47 PM | BO26: MARIAM | BP26: 6/23/2026 8:45 PM | BR26: NAYERA | BS26: 6/17/2026 7:51 PM | BU26: NORHAN | BV26: 6/18/2026 10:52 AM | BX26: MSAEED | BY26: 6/24/2026 9:24 PM | CB26: SHAHD | CC26: 6/17/2026 10:54 AM | CE26: Ibrahimsobh | CF26: 6/25/2026 12:09 PM | CG26: 1 | CH26: Taliahany | CI26: 6/17/2026 11:11 AM | CK26: TASNEEM | CL26: 6/25/2026 11:27 AM | CM26: 0.25 | CN26: YARAMEDHAT | CO26: 6/15/2026 7:02 PM | CQ26: HABEBA | CR26: 6/18/2026 7:48 PM
A27: Abdrahman mohamed ahmed | B27: 6/21/2026 7:59 PM | D27: Adham saad monir saad | E27: 6/18/2026 7:47 PM | G27: Saturday | H27: 6/20/2026 12:11 PM | J27: AHMEDNABEL | K27: 6/15/2026 7:02 PM | N27: 30-6-2026 | O27: 0.25 | P27: MAKRAM | Q27: 6/17/2026 7:45 PM | S27: ALIWAEL | T27: 6/16/2026 7:51 PM | U27: 0 | V27: AML | W27: 6/20/2026 12:01 PM | AB27: KAREEM | AC27: 6/18/2026 7:00 PM | AE27: MHELMY | AF27: 6/15/2026 7:48 PM | AH27: MANAR | AI27: 6/14/2026 10:56 AM | AK27: ZEINAB | AL27: 6/21/2026 10:52 AM | AN27: Eslamhesen | AO27: 6/21/2026 11:05 AM | AT27: meeting | AU27: 6/21/2026 12:07 PM | AW27: HAIDY | AX27: 6/16/2026 11:11 AM | AZ27: MOHAMEDELSAYED | BA27: 6/16/2026 12:47 PM | BB27: 1 | BC27: meeting | BD27: 6/17/2026 3:03 PM | BF27: Bassanti | BG27: 6/28/2026 10:53 AM | BI27: DAHAB | BJ27: 6/21/2026 7:59 PM | BL27: JANA | BM27: 6/20/2026 2:10 PM | BO27: meeting | BP27: 6/24/2026 2:25 PM | BR27: NAYERA | BS27: 6/18/2026 11:13 AM | BU27: NORHAN | BV27: 6/18/2026 10:53 AM | BX27: meeting informed by samaher | BY27: 46203.892 | CB27: SHAHD | CC27: 6/17/2026 8:04 PM | CE27: Ibrahimsobh | CF27: 6/25/2026 7:35 PM | CH27: Taliahany | CI27: 6/18/2026 11:13 AM | CK27: no in | CL27: 46201.477 | CN27: YARAMEDHAT | CO27: 6/15/2026 7:03 PM | CQ27: HABEBA | CR27: 6/21/2026 11:14 AM
A28: Abdrahman mohamed ahmed | B28: 6/22/2026 2:12 PM | C28: 1 | D28: Adham saad monir saad | E28: 6/18/2026 8:59 PM | G28: AHMEDMAGDY | H28: 6/20/2026 6:55 PM | J28: 2 days rased agazto | K28: 6/16/2026 11:18 AM | P28: meeting | Q28: 6/18/2026 12:22 PM | R28: 0 | S28: meeting | T28: 6/17/2026 3:48 PM | U28: 0 | V28: AML | W28: 6/20/2026 7:07 PM | AB28: KAREEM | AC28: 6/20/2026 1:02 PM | AE28: MHELMY | AF28: 6/16/2026 11:22 AM | AG28: 0.25 | AH28: MANAR | AI28: 6/14/2026 7:39 PM | AK28: ZEINAB | AL28: 6/21/2026 8:00 PM | AN28: Eslamhesen | AO28: 6/21/2026 9:13 PM | AT28: DAWOD | AU28: 6/21/2026 8:29 PM | AW28: HAIDY | AX28: 6/17/2026 1:27 PM | AY28: 1 | AZ28: MOHAMEDELSAYED | BA28: 6/16/2026 8:07 PM | BC28: meeting | BD28: 6/18/2026 12:42 PM | BE28: 0 | BG28: 46202.485 | BH28: 0.5 | BI28: DAHAB | BJ28: 6/22/2026 10:56 AM | BL28: JANA | BM28: 6/20/2026 6:44 PM | BO28: MARIAM | BP28: 6/24/2026 8:07 PM | BR28: NAYERA | BS28: 6/18/2026 9:22 PM | BU28: NORHAN | BV28: 6/18/2026 7:18 PM | CB28: SHAHD | CC28: 6/18/2026 10:56 AM | CF28: 6 days annual | CH28: Taliahany | CI28: 6/18/2026 7:43 PM | CK28: nor 2a63 29-6 | CL28: 46202.477 | CN28: YARAMEDHAT | CO28: 6/16/2026 11:12 AM | CQ28: HABEBA | CR28: 6/21/2026 8:05 PM
A29: Abdrahman mohamed ahmed | B29: 6/22/2026 9:37 PM | D29: Adham saad monir saad | E29: 6/20/2026 8:31 PM | G29: AHMEDMAGDY | H29: 6/20/2026 6:55 PM | J29: AHMEDNABEL | K29: 6/21/2026 11:03 AM | P29: MAKRAM | Q29: 6/18/2026 7:09 PM | S29: ALIWAEL | T29: 6/17/2026 8:08 PM | U29: 0 | V29: AML | W29: 6/21/2026 10:56 AM | AB29: KAREEM | AC29: 6/20/2026 6:53 PM | AE29: MHELMY | AF29: 6/17/2026 11:01 AM | AH29: MANAR | AI29: 6/15/2026 10:47 AM | AK29: ZEINAB | AL29: 6/21/2026 8:00 PM | AN29: Eslamhesen | AO29: 6/22/2026 11:02 AM | AT29: DAWOD | AU29: 6/22/2026 11:59 AM | AW29: off | AX29: 0.77083333 | AZ29: MOHAMEDELSAYED | BA29: 6/17/2026 12:22 PM | BB29: 1 | BC29: ANDREW | BD29: 6/18/2026 7:54 PM | BG29: 46203.474 | BH29: 0.25 | BI29: DAHAB | BJ29: 6/22/2026 8:19 PM | BL29: JANA | BM29: 6/21/2026 11:24 AM | BN29: 0.25 | BO29: MARIAM | BP29: 6/25/2026 11:36 AM | BQ29: 0.5 | BR29: NAYERA | BS29: 6/20/2026 12:13 PM | BU29: NORHAN | BV29: 6/21/2026 10:50 AM | CB29: SHAHD | CC29: 6/18/2026 7:19 PM | CF29: 22-6 | CH29: Taliahany | CI29: 6/20/2026 1:57 PM | CK29: no in | CL29: 46203.477 | CM29: 0.25 | CN29: YARAMEDHAT | CO29: 6/17/2026 10:54 AM | CQ29: HABEBA | CR29: 6/22/2026 11:03 AM
A30: Abdrahman mohamed ahmed | B30: 6/23/2026 9:25 AM | D30: Adham saad monir saad | E30: 6/21/2026 11:28 AM | F30: 0.25 | G30: excuse | H30: 6/21/2026 11:22 AM | I30: 0.25 | J30: AHMEDNABEL | K30: 6/21/2026 7:00 PM | P30: MAKRAM | Q30: 6/20/2026 12:57 PM | R30: ? | S30: 18/6 | T30: 6/20/2026 2:00 PM | V30: AML | W30: 6/21/2026 7:59 PM | AB30: excuse | AC30: 6/21/2026 12:04 PM | AD30: 0 | AE30: MHELMY | AF30: 6/17/2026 8:07 PM | AH30: MANAR | AI30: 6/15/2026 7:41 PM | AK30: ZEINAB | AL30: 6/22/2026 10:35 AM | AN30: Eslamhesen | AO30: 6/22/2026 8:24 PM | AT30: DAWOD | AU30: 6/22/2026 8:34 PM | AX30: no form | AZ30: MOHAMEDELSAYED | BA30: 6/17/2026 8:11 PM | BC30: ANDREW | BD30: 6/21/2026 11:34 AM | BE30: 0.5 | BI30: excuse | BJ30: 6/23/2026 11:57 AM | BK30: 0 | BL30: JANA | BM30: 6/21/2026 6:45 PM | BO30: MARIAM | BP30: 6/25/2026 7:00 PM | BR30: NAYERA | BS30: 6/20/2026 7:14 PM | BU30: NORHAN | BV30: 6/21/2026 10:52 AM | CB30: SHAHD | CC30: 6/20/2026 12:00 PM | CF30: 46201.816 | CG30: 1 | CH30: Taliahany | CI30: 6/20/2026 7:14 PM | CN30: YARAMEDHAT | CO30: 6/17/2026 7:00 PM | CQ30: HABEBA | CR30: 6/22/2026 8:13 PM
A31: Abdrahman mohamed ahmed | B31: 6/23/2026 9:16 PM | D31: Adham saad monir saad | E31: 6/21/2026 8:03 PM | G31: AHMEDMAGDY | H31: 6/21/2026 11:22 AM | J31: AHMEDNABEL | K31: 6/22/2026 11:04 AM | P31: MAKRAM | Q31: 6/20/2026 6:55 PM | S31: ALIWAEL | T31: 6/20/2026 6:53 PM | U31: 0 | V31: AML | W31: 6/22/2026 10:50 AM | AB31: KAREEM | AC31: 6/21/2026 8:24 PM | AE31: MHELMY | AF31: 6/18/2026 11:25 AM | AG31: 0 | AH31: MANAR | AI31: 6/16/2026 11:11 AM | AK31: ZEINAB | AL31: 6/22/2026 5:24 PM | AN31: excuse | AO31: 6/23/2026 11:23 AM | AP31: 0 | AT31: meeting | AU31: 6/23/2026 12:04 PM | AZ31: MOHAMEDELSAYED | BA31: 6/18/2026 11:56 AM | BB31: 0.5 | BC31: ANDREW | BD31: 6/21/2026 9:13 PM | BI31: DAHAB | BJ31: 6/23/2026 9:16 PM | BL31: JANA | BM31: 6/22/2026 11:26 AM | BN31: 0.25 | BO31: MARIAM | BP31: 6/28/2026 11:40 AM | BQ31: 0.5 | BR31: excuse | BS31: 6/21/2026 12:15 PM | BU31: NORHAN | BV31: 6/21/2026 6:58 PM | CB31: SHAHD | CC31: 6/20/2026 7:07 PM | CF31: 46202.816 | CG31: 1 | CH31: Taliahany | CI31: 6/21/2026 1:15 PM | CJ31: 1 | CN31: YARAMEDHAT | CO31: 6/18/2026 10:53 AM | CQ31: HABEBA | CR31: 6/23/2026 11:12 AM
A32: Abdrahman mohamed ahmed | B32: 6/24/2026 11:00 AM | D32: excuse | E32: 6/22/2026 12:25 PM | F32: 0 | G32: AHMEDMAGDY | H32: 6/21/2026 5:57 PM | J32: AHMEDNABEL | K32: 6/22/2026 11:07 AM | P32: meeting | Q32: 6/21/2026 12:10 PM | S32: meeting | T32: 6/21/2026 12:57 PM | U32: 0 | V32: AML | W32: 6/22/2026 8:12 PM | AB32: KAREEM | AC32: 6/22/2026 11:28 AM | AD32: 0.25 | AE32: MHELMY | AF32: 6/18/2026 7:48 PM | AH32: MANAR | AI32: 6/16/2026 2:58 PM | AK32: ZEINAB | AL32: 6/23/2026 10:47 AM | AN32: Eslamhesen | AO32: 6/23/2026 9:30 PM | AT32: DAWOD | AU32: 6/23/2026 9:43 PM | AZ32: MOHAMEDELSAYED | BA32: 6/18/2026 7:34 PM | BC32: ANDREW | BD32: 6/22/2026 12:32 PM | BI32: DAHAB | BJ32: 6/24/2026 11:09 AM | BL32: JANA | BM32: 6/22/2026 8:12 PM | BP32: 5 days annual | BR32: NAYERA | BS32: 6/21/2026 7:36 PM | BU32: NORHAN | BV32: 6/22/2026 10:58 AM | CB32: SHAHD | CC32: 6/21/2026 10:56 AM | CH32: Taliahany | CI32: 6/21/2026 7:59 PM | CN32: YARAMEDHAT | CO32: 6/18/2026 5:00 PM | CQ32: HABEBA | CR32: 6/23/2026 11:12 AM
A33: Abdrahman mohamed ahmed | B33: 6/25/2026 12:01 AM | D33: Adham saad monir saad | E33: 6/22/2026 8:36 PM | G33: AHMEDMAGDY | H33: 6/22/2026 11:08 AM | J33: AHMEDNABEL | K33: 6/23/2026 11:13 AM | P33: 1 | Q33: 6/21/2026 8:33 PM | S33: ALIWAEL | T33: 6/21/2026 8:24 PM | U33: 0 | V33: AML | W33: 6/23/2026 11:07 AM | AB33: KAREEM | AC33: 6/22/2026 8:17 PM | AE33: meeting | AF33: 6/20/2026 2:10 PM | AH33: meeting | AI33: 6/17/2026 1:25 PM | AK33: ZEINAB | AL33: 6/23/2026 7:58 PM | AN33: Eslamhesen | AO33: 6/24/2026 11:12 AM | AT33: meeting | AU33: 6/24/2026 12:15 PM | AZ33: MOHAMEDELSAYED | BA33: 6/18/2026 7:41 PM | BC33: ANDREW | BD33: 6/22/2026 8:23 PM | BI33: DAHAB | BJ33: 6/24/2026 8:42 PM | BL33: JANA | BM33: 6/23/2026 11:22 AM | BN33: 0.25 | BP33: 46203.47 | BQ33: 0.25 | BR33: NAYERA | BS33: 6/22/2026 10:59 AM | BU33: NORHAN | BV33: 6/22/2026 11:04 AM | CB33: SHAHD | CC33: 6/21/2026 8:28 PM | CH33: Taliahany | CI33: 6/22/2026 2:11 PM | CJ33: 1 | CN33: YARAMEDHAT | CO33: 6/21/2026 10:54 AM | CQ33: HABEBA | CR33: 6/23/2026 6:26 PM
A34: Abdrahman mohamed ahmed | B34: 6/25/2026 11:02 AM | D34: Adham saad monir saad | E34: 6/23/2026 11:16 AM | G34: AHMEDMAGDY | H34: 6/22/2026 8:24 PM | J34: AHMEDNABEL | K34: 6/23/2026 11:14 AM | P34: MAKRAM | Q34: 6/23/2026 11:28 AM | R34: 0.25 | S34: meeting | T34: 6/22/2026 5:39 PM | V34: AML | W34: 6/23/2026 8:15 PM | AB34: KAREEM | AC34: 6/23/2026 11:19 AM | AD34: 0.25 | AE34: MHELMY | AF34: 6/20/2026 6:45 PM | AH34: MANAR | AI34: 6/17/2026 7:54 PM | AK34: ZEINAB | AL34: 6/24/2026 10:39 AM | AN34: Eslamhesen | AO34: 6/24/2026 9:25 PM | AT34: DAWOD | AU34: 6/24/2026 8:57 PM | AZ34: MOHAMEDELSAYED | BA34: 6/20/2026 12:42 PM | BC34: ANDREW | BD34: 6/23/2026 11:31 AM | BE34: 0.5 | BI34: DAHAB | BJ34: 6/25/2026 11:10 AM | BL34: JANA | BM34: 6/23/2026 8:16 PM | BR34: NAYERA | BS34: 6/22/2026 11:00 AM | BU34: NORHAN | BV34: 6/22/2026 6:59 PM | CB34: SHAHD | CC34: 6/22/2026 10:53 AM | CH34: Taliahany | CI34: 6/22/2026 9:37 PM | CN34: YARAMEDHAT | CO34: 6/21/2026 7:00 PM | CQ34: HABEBA | CR34: 6/25/2026 10:51 AM | CS34: 1
A35: Abdrahman mohamed ahmed | B35: 6/25/2026 9:08 PM | D35: Adham saad monir saad | E35: 6/23/2026 9:08 PM | G35: AHMEDMAGDY | H35: 6/23/2026 11:11 AM | J35: AHMEDNABEL | K35: 6/23/2026 7:00 PM | P35: MAKRAM | Q35: 6/23/2026 8:45 PM | S35: ALIWAEL | T35: 6/22/2026 7:43 PM | V35: AML | W35: 6/24/2026 10:55 AM | AB35: KAREEM | AC35: 6/23/2026 8:44 PM | AE35: MHELMY | AF35: 6/21/2026 11:24 AM | AG35: 0.25 | AH35: MANAR | AI35: 6/18/2026 10:51 AM | AK35: ZEINAB | AL35: 6/24/2026 8:12 PM | AN35: Eslamhesen | AO35: 6/24/2026 9:28 PM | AT35: meeting | AU35: 6/25/2026 8:11 PM | AZ35: MOHAMEDELSAYED | BA35: 6/20/2026 7:06 PM | BC35: ANDREW | BD35: 6/23/2026 10:23 PM | BI35: DAHAB | BJ35: 6/25/2026 7:38 PM | BL35: meeting | BM35: 6/24/2026 1:32 PM | BR35: NAYERA | BS35: 6/22/2026 7:07 PM | BU35: NORHAN | BV35: 6/23/2026 11:06 AM | CB35: SHAHD | CC35: 6/22/2026 8:28 PM | CH35: Taliahany | CI35: 6/23/2026 11:18 AM | CN35: YARAMEDHAT | CO35: 6/22/2026 10:43 AM | CQ35: HABEBA | CR35: 6/25/2026 7:07 PM
A36: Abdrahman mohamed ahmed | B36: 6/27/2026 5:00 PM | D36: Adham saad monir saad | E36: 6/24/2026 11:17 AM | F36: 0.25 | G36: AHMEDMAGDY | H36: 6/23/2026 8:43 PM | J36: AHMEDNABEL | K36: 6/25/2026 11:11 AM | P36: meeting | Q36: 6/24/2026 1:32 PM | S36: ALIWAEL | T36: 6/23/2026 12:20 PM | U36: 1 | V36: AML | W36: 6/24/2026 8:21 PM | AB36: KAREEM | AC36: 6/24/2026 11:16 AM | AD36: 0.25 | AE36: MHELMY | AF36: 6/21/2026 8:00 PM | AH36: MANAR | AI36: 6/18/2026 10:51 AM | AK36: ZEINAB | AL36: 6/25/2026 10:32 AM | AN36: excuse | AO36: 6/25/2026 11:23 AM | AP36: 0 | AT36: DAWOD | AU36: 6/28/2026 11:51 AM | AV36: 0.5 | AZ36: meeting | BA36: 6/21/2026 12:07 PM | BC36: ANDREW | BD36: 6/24/2026 11:53 AM | BE36: 0.5 | BI36: DAHAB | BJ36: 6/25/2026 7:39 PM | BL36: JANA | BM36: 6/24/2026 8:05 PM | BR36: NAYERA | BS36: 6/23/2026 10:52 AM | BU36: NORHAN | BV36: 6/23/2026 11:11 AM | CB36: SHAHD | CC36: 6/23/2026 11:04 AM | CH36: Taliahany | CI36: 6/23/2026 9:16 PM | CN36: YARAMEDHAT | CO36: 6/22/2026 6:59 PM | CQ36: excuse | CR36: 6/28/2026 11:21 AM | CS36: 0
A37: nor kan 2a63 on Monday\ | B37: 46201 | D37: Adham saad monir saad | E37: 6/24/2026 8:17 PM | G37: AHMEDMAGDY | H37: 6/24/2026 11:16 AM | I37: 0.25 | J37: AHMEDNABEL | K37: 6/25/2026 7:00 PM | P37: MAKRAM | Q37: 6/24/2026 8:12 PM | S37: ALIWAEL | T37: 6/23/2026 8:45 PM | V37: AML | W37: 6/25/2026 10:55 AM | AB37: KAREEM | AC37: 6/24/2026 8:49 PM | AE37: MHELMY | AF37: 6/22/2026 11:26 AM | AG37: 0.25 | AH37: MANAR | AI37: 6/18/2026 7:06 PM | AK37: ZEINAB | AL37: 6/25/2026 5:33 PM | AN37: Eslamhesen | AO37: 6/25/2026 8:50 PM | AU37: 46202.035 | AV37: 1 | AZ37: MOHAMEDELSAYED | BA37: 6/22/2026 12:00 PM | BC37: ANDREW | BD37: 6/24/2026 9:42 PM | BJ37: 46201.503 | BK37: 1 | BL37: JANA | BM37: 6/25/2026 11:09 AM | BR37: NAYERA | BS37: 6/23/2026 11:11 AM | BU37: NORHAN | BV37: 6/23/2026 6:13 PM | CB37: SHAHD | CC37: 6/24/2026 11:05 AM | CH37: Taliahany | CI37: 6/24/2026 11:12 AM | CN37: YARAMEDHAT | CO37: 6/23/2026 10:50 AM
B38: 46202 | C38: 0.5 | D38: Adham saad monir saad | E38: 6/25/2026 11:16 AM | F38: 0.25 | G38: AHMEDMAGDY | H38: 6/24/2026 8:07 PM | J38: AHMEDNABEL | K38: 6/28/2026 11:06 AM | P38: MAKRAM | Q38: 6/25/2026 11:20 AM | R38: 0.25 | S38: meeting | T38: 6/24/2026 2:02 PM | V38: AML | W38: 6/25/2026 7:11 PM | AB38: KAREEM | AC38: 6/25/2026 11:02 AM | AE38: MHELMY | AF38: 6/22/2026 8:15 PM | AH38: MANAR | AI38: 6/21/2026 10:56 AM | AK38: ZEINAB | AL38: 6/28/2026 10:36 AM | AN38: Eslamhesen | AO38: 6/28/2026 11:03 AM | AZ38: MOHAMEDELSAYED | BA38: 6/22/2026 8:34 PM | BC38: ANDREW | BD38: 6/28/2026 10:58 AM | BJ38: 46203.472 | BK38: 0.25 | BL38: JANA | BM38: 6/25/2026 11:09 AM | BR38: NAYERA | BS38: 6/23/2026 8:52 PM | BU38: NORHAN | BV38: 6/24/2026 10:43 AM | CB38: SHAHD | CC38: 6/25/2026 10:56 AM | CH38: excuswe | CI38: 6/25/2026 12:01 AM | CJ38: 0 | CN38: YARAMEDHAT | CO38: 6/23/2026 10:55 AM
B39: 46203 | C39: 1 | D39: Adham saad monir saad | E39: 6/25/2026 9:20 PM | G39: AHMEDMAGDY | H39: 6/25/2026 11:12 AM | K39: 46202 | P39: MAKRAM | Q39: 6/25/2026 7:04 PM | S39: ALIWAEL | T39: 6/24/2026 9:23 PM | V39: AML | W39: 6/28/2026 10:54 AM | AB39: KAREEM | AC39: 6/25/2026 7:00 PM | AE39: MHELMY | AF39: 6/23/2026 11:22 AM | AG39: 0.25 | AH39: MANAR | AI39: 6/21/2026 10:58 AM | AO39: 46202.46 | AZ39: meeting | BA39: 6/23/2026 12:04 PM | BD39: 46202.523 | BL39: JANA | BM39: 6/25/2026 6:58 PM | BR39: NAYERA | BS39: 6/24/2026 11:02 AM | BU39: NORHAN | BV39: 6/24/2026 6:58 PM | CB39: SHAHD | CC39: 6/28/2026 11:03 AM | CI39: 6/25/2026 10:40 AM | CN39: YARAMEDHAT | CO39: 6/23/2026 7:00 PM
E40: 6/28/2026 11:37 AM | F40: 0.5 | G40: AHMEDMAGDY | H40: 6/25/2026 7:01 PM | P40: MAKRAM | Q40: 6/28/2026 11:07 AM | S40: meeting | T40: 6/25/2026 2:06 PM | W40: 46202.502 | X40: 1 | AB40: KAREEM | AC40: 6/28/2026 11:07 AM | AE40: MHELMY | AF40: 6/23/2026 8:16 PM | AH40: MANAR | AI40: 6/21/2026 7:57 PM | AO40: 46203.46 | AP40: 0.5 | AZ40: meeting | BA40: 6/24/2026 12:15 PM | BD40: 46203.526 | BL40: JANA | BM40: 6/28/2026 11:16 AM | BN40: 0.25 | BR40: NAYERA | BS40: 6/24/2026 7:25 PM | BU40: NORHAN | BV40: 6/25/2026 10:54 AM | CH40: Taliahany | CI40: 6/25/2026 8:41 PM | CN40: YARAMEDHAT | CO40: 6/24/2026 10:50 AM
...

Sheet Sheet5
B1: Marts - Bank - Sales | J1: KHALED - Bank
A2: # | B2: Name | C2: Basic | D2: Absence | E2: Late D | F2: Total Cuts | G2: Loan | H2: Net | J2: # | K2: Name | L2: Basic | M2: Absence | N2: Late D | O2: Loan | P2: Net
A3: 1 | B3: Ali Wael Khedr Khamis | C3: 18000 | D3: 2 | E3: 2.75 | F3: 2.75 | G3: 5000 | H3: 11350 | J3: 1 | K3: Saad Mounir Saad | L3: 15000 | M3: 0 | N3: 0 | O3: 0 | P3: 15000
A4: 2 | B4: Ahmed Mohamed Ahmed Nashat | C4: 7000 | D4: 14 | E4: 3 | F4: 17 | G4: 0 | H4: 2975 | J4: 2 | K4: Adham Saad Monir | L4: 7000 | M4: 5 | N4: 3.5 | O4: 0 | P4: =#REF! -> #REF!
A5: 3 | B5: Fatma Anwar Abdelwahed hasballah | C5: 7000 | D5: 4 | E5: 0.25 | F5: 4.25 | G5: 0 | H5: 5775 | J5: 3 | K5: Ahmed Nabil | L5: 10000 | M5: 0 | N5: 0.25 | O5: 0 | P5: 9917
A6: 4 | B6: Habiba Saber Abdelhay Abdelhafez | C6: 8000 | D6: 3 | E6: 0 | F6: 1 | G6: 0 | H6: 7200
A7: 5 | B7: Ibrahem soph salama | C7: 10000 | D7: 7 | E7: 5 | F7: 5 | G7: 0 | H7: 5000 | L7: Khaled - Cash
A8: 6 | B8: Islam Hussien Ibrahim Abdelkader | C8: 8000 | D8: 0 | E8: 1 | F8: 1 | G8: 0 | H8: 7733 | J8: # | K8: Name | L8: Basic | M8: Absence | N8: Late D | O8: Loan | P8: Net
A9: 7 | B9: Janna Mohamed Mostafa Ghanem | C9: 9000 | D9: 3 | E9: 2 | F9: 5 | G9: 0 | H9: 7500 | J9: 1 | K9: Yara Medhat | L9: 7000 | M9: 0 | N9: 0 | O9: 0 | P9: 7000
A10: 8 | B10: kholod Mohamed Ahmed | C10: 8000 | D10: 0 | E10: 0 | F10: 0 | G10: 0 | H10: 8000 | P10: =SUM(P3:P9) -> #REF!
A11: 9 | B11: Mariam Mohamed Youssef Hassan | C11: 8000 | D11: 0 | E11: 1.75 | F11: 1.75 | G11: 0 | H11: 7533
A12: 10 | B12: Mohamed Akram Sayed Abdelmaksod | C12: 20000 | D12: 0 | E12: 2.75 | F12: 2.75 | G12: 0 | H12: 18500
A13: 11 | B13: Mohamed Elsayed Ezzat Almorsy | C13: 18000 | D13: 0 | E13: 8 | F13: 8 | G13: 0 | H13: =#REF! -> #REF!
A14: 12 | B14: Mohamed Helmy Foad Ahmed essa | C14: 7000 | D14: 0 | E14: 1.25 | F14: 1.25 | G14: 0 | H14: 6708
A15: 13 | B15: Mohamed Khalid Abdelaziz Dawood | C15: 12000 | D15: 0 | E15: 3.5 | F15: 3.5 | G15: 0 | H15: 10600
A16: 14 | B16: Tasneem Shokry Mohamed Mohamed | C16: 20000 | D16: 6 | E16: 2.75 | F16: 8.75 | G16: 0 | H16: =#REF! -> #REF!
A17: 15 | B17: Zienab Naser Mahmoud Abdelrazek | C17: 9000 | D17: 1 | E17: 1.5 | F17: 2.5 | G17: 0 | H17: 8250
H18: =SUM(H3:H17) -> #REF!
B21: Marts - Bank - Back Office
A22: # | B22: Name | C22: Basic | D22: Absence | E22: Late D | F22: Total Cuts | G22: Loan | H22: Net
A23: 1 | B23: Ahmed Magdy Youssef Selim | C23: 100000 | D23: 0 | E23: 0 | F23: 0 | G23: 0 | H23: 100000
A24: 2 | B24: Bassanti Ibrahim Hilal Shaaban | C24: 15000 | D24: 0 | E24: 0 | F24: 0 | G24: 0 | H24: 15000
A25: 3 | B25: Khalid Alwakkad | C25: 30000 | D25: 0 | E25: 0 | F25: 0 | G25: 0 | H25: 30000
A26: 4 | B26: Hossney ahmed hussien | C26: 7000 | D26: 0 | E26: 0 | F26: 2 | G26: 1200 | H26: 5800
A27: 5 | B27: Nayera Mohamed Mohamed Abdolmoaaty | C27: 12000 | D27: 2 | E27: 0 | F27: 0 | G27: 0 | H27: 11200
A28: 6 | B28: Talia Hani Ali Kotb | C28: 15000 | D28: 0 | E28: 3 | F28: 3 | G28: 0 | H28: 13500
A29: 7 | B29: Abdelrahman Mohamed Ahmed Mohamed | C29: 10000 | D29: 0 | E29: 6.25 | F29: 0 | G29: 1351 | H29: 6899
A30: 8 | B30: Norhan Diab Ahmed | C30: 12000 | D30: 0 | E30: 0 | F30: 0 | G30: 0 | H30: 12000
H31: =SUM(H23:H30) -> 194399
A34: Marts - Cash - Sales
A35: # | B35: Name | C35: Basic | D35: Absence | E35: Late D | F35: Total Cuts | G35: Loan | H35: Net
A36: 1 | B36: Amal Atef Mohamed Moshthe | C36: 7000 | D36: 1 | E36: 0.25 | F36: 1.25 | G36: 0 | H36: 6708
A37: 2 | B37: Andrew Fayez Rashad Sadek | C37: 7000 | D37: 1 | E37: 2 | F37: 3 | G37: 0 | H37: 6300
A38: 3 | B38: Manar Ali Mohamed Abdelmogle | C38: 7000 | D38: 0 | E38: 0 | F38: 0 | G38: 0 | H38: 7000
A39: 4 | B39: Mohamed Saeed Ahmed Alsadek Khalaf | C39: 40000 | D39: 6 | E39: 7.25 | F39: 13.25 | G39: 0 | H39: 22333
A40: 5 | B40: Haidy Mohamed Shebl Alfaramawy | C40: 9000 | D40: 0 | E40: 1.5 | F40: 1.5 | G40: 0 | H40: 2850
A41: 6 | B41: Ahmed Amr foad Mohamed | C41: 10000 | D41: 3 | E41: 2.5 | F41: 5.5 | G41: 0
A42: 7 | B42: Amal Ahmed Abbas Ebrahim | C42: 9000 | D42: 22 | E42: 0.25 | F42: 22.25 | G42: 0 | H42: 2325
A43: 8 | B43: Shahd Magdy Salah Abood | C43: 7000 | D43: 0 | E43: 0 | F43: 0 | G43: 0 | H43: 7000
A44: 9 | B44: Amira Lotfi Mohamed Lotfi | C44: 7000 | D44: 22 | E44: 0 | F44: 22 | G44: 0 | H44: 1867
...

Sheet all employees
A1: # | B1: CASH | C1: NET CASH | D1: Column1
A2: 1 | B2: Mohamed Osama Hassanen Ahmed | C2: 6242 | D2: تصفية وانتظار راتب
A3: 2 | B3: Ahmed Magdy Fahmy Mohamed | C3: 11266 | D3: تصفية وانتظار راتب
A4: 3 | B4: Ahmed Nabil Hassan Ali Hassan | C4: 9917 | D4: d
A5: 4 | B5: Abdelrahman Mohamed Ahmed Mohamed | C5: =Sheet3!N3 -> 6899 | D5: d
A6: 5 | B6: Khalid Alwakkad | C6: 30000 | D6: باقي له 20K
A7: 6 | B7: Mohamed Elsayed Ezzat Almorsy | C7: 8800
A8: 7 | B8: Mohamed Khalid Abdelaziz Dawood | C8: 5600
A9: 8 | B9: Saad Mounir Saad Mohamed | C9: 15000
A10: 9 | B10: Talia Hani Ali Kotb | C10: 13500 | D10: d
A11: 10 | B11: Amira Lotfi Mohamed Lotfi | C11: 1867 | D11: d
A12: 11 | B12: Amal Ahmed Abbas Ebrahim | C12: 2325 | D12: d
A13: 12 | B13: Amal Atef Mohamed Moshthe | C13: 6708 | D13: تصفية وانتظار راتب
A14: 13 | B14: Andrew Fayez Rashad Sadek | C14: 6300 | D14: d
A15: 14 | B15: Haidy Mohamed Shebl Alfaramawy | C15: 2850 | D15: تصفية وانتظار راتب
A16: 15 | B16: Mohamed Akram Sayed Abdelmaksod | C16: 18500 | D16: d
A17: 16 | B17: Mohamed Saeed Ahmed Alsadek Khalaf | C17: 17333
A18: 17 | B18: Kareem Mohamed Hussien Sayed | C18: 6592 | D18: تصفية وانتظار راتب
A19: 18 | B19: Manar Ali Mohamed Abdelmogle | C19: 7000 | D19: d
A20: 19 | B20: Ahmed Nagib | C20: 3000 | D20: 549
A21: 20 | B21: Mohamed Ahmed Mohamed 3mo | C21: 7000 | D21: d
A22: 21 | B22: Shahd Magdy Salah Abood | C22: 7000 | D22: d
A23: 22 | B23: Yara Medhat Ghaleb Ali | C23: 7000 | D23: d
C24: =SUM(C2:C23) -> 200699
A26: BANK TRANSFER
A27: # | B27: NAME | C27: NET
A28: 1 | B28: Adham Saad Monir Saad | C28: 3850
A29: 2 | B29: Ahmed Mohamed Nashaat | C29: 2975
A30: 3 | B30: Ali Wael Khedr Khamis | C30: 11350
A31: 4 | B31: Bassanti Ibrahim Hilal Shaaban | C31: 15000
A32: 5 | B32: kholod Mohamed Ahmed | C32: 8000
A33: 6 | B33: Fatma Anwar Abdelwahed hasballah | C33: 5775
A34: 7 | B34: Habiba Saber Abdelhay Abdelhafez | C34: 7200
A35: 8 | B35: Hossney ahmed hussien | C35: 5800
A36: 9 | B36: Ibrahem soph salama | C36: 5000
A37: 10 | B37: Islam Hussien Ibrahim Abdelkader | C37: 7733
A38: 11 | B38: Janna Mohamed Mostafa Ghanem | C38: 7500
A39: 12 | B39: Mariam Mohamed Youssef Hassan | C39: 7533.3333
... A44: 17 | B44: Zienab Naser Mahmoud Abdelrazek | C44: 8250
C45: =SUBTOTAL(109,C28:C44) -> 142041.33

Sheet Sheet3
C1: 46174
A2: N | B2: N | C2: Name | D2: Basic Salary | E2: Days | F2: Absence Days | G2: Day Value | H2: warning | I2: Late Deduction | J2: Total Cuts | K2: extra from last month | L2: Loan | M2: Total cuts Cash | N2: Net | O2: Working days | P2: notes
A3: b | B3: Marts | C3: Abdelrahman Mohamed Ahmed Mohamed | D3: 10000 | E3: 30 | F3: 0 | G3: =Table352[[#This Row],[Basic Salary]]/Table352[[#This Row],[Days]] -> 333.33333 | H3: 0 | I3: =(FPs!C1) -> 5.25 | J3: =Table352[[#This Row],[Late Deduction]]+Table352[[#This Row],[Absence Days]]+Table352[[#This Row],[warning]] -> 5.25 | K3: 0 | L3: 1351 | M3: =Table352[[#This Row],[Total Cuts ]]*Table352[[#This Row],[Day Value]] -> 1750 | N3: =Table352[[#This Row],[Basic Salary]]-(Table352[[#This Row],[Total cuts Cash]]+Table352[[#This Row],[Loan]])+Table352[[#This Row],[extra from last month]] -> 6899 | O3: d
A4: b | B4: Khaled's | C4: Adham Saad Monir Saad | D4: 7000 | E4: 30 | F4: 5 | G4: =Table352[[#This Row],[Basic Salary]]/Table352[[#This Row],[Days]] -> 233.33333 | H4: 0 | I4: =FPs!F1 -> 3.5 | J4: =Table352[[#This Row],[Late Deduction]]+Table352[[#This Row],[Absence Days]]+Table352[[#This Row],[warning]] -> 8.5 | K4: 0 | L4: 0 | M4: =Table352[[#This Row],[Total Cuts ]]*Table352[[#This Row],[Day Value]] -> 1983.3333 | N4: =Table352[[#This Row],[Basic Salary]]-(Table352[[#This Row],[Total cuts Cash]]+Table352[[#This Row],[Loan]])+Table352[[#This Row],[extra from last month]] -> 5016.6667 | O4: d
A5: c | B5: Marts | C5: Ahmed Magdy Fahmy Mohamed | D5: 13000 | E5: 30 | F5: 3 | G5: =Table352[[#This Row],[Basic Salary]]/Table352[[#This Row],[Days]] -> 433.33333 | H5: 0 | I5: =FPs!I1 -> 4 | J5: =Table352[[#This Row],[Late Deduction]]+Table352[[#This Row],[Absence Days]]+Table352[[#This Row],[warning]] -> 7 | K5: 1299 | L5: 0 | M5: =Table352[[#This Row],[Total Cuts ]]*Table352[[#This Row],[Day Value]] -> 3033.3333 | N5: =Table352[[#This Row],[Basic Salary]]-(Table352[[#This Row],[Total cuts Cash]]+Table352[[#This Row],[Loan]])+Table352[[#This Row],[extra from last month]] -> 11265.667 | P5: له 3 ايام يضافوا للشهر يونيه بمعرفة نجيب
A6: b | B6: Marts | C6: Ahmed Magdy Youssef Selim | D6: 100000 | E6: 30 | F6: 0 | G6: =Table352[[#This Row],[Basic Salary]]/Table352[[#This Row],[Days]] -> 3333.3333 | H6: 0 | I6: 0 | J6: =Table352[[#This Row],[Late Deduction]]+Table352[[#This Row],[Absence Days]]+Table352[[#This Row],[warning]] -> 0 | K6: 0 | L6: 0 | M6: 0 | N6: =Table352[[#This Row],[Basic Salary]]-(Table352[[#This Row],[Total cuts Cash]]+Table352[[#This Row],[Loan]])+Table352[[#This Row],[extra from last month]] -> 100000
A7: b | B7: Khaled's | C7: Ahmed Mohamed Nashaat | D7: 7000 | E7: 30 | F7: 14 | G7: =Table352[[#This Row],[Basic Salary]]/Table352[[#This Row],[Days]] -> 233.33333 | I7: =FPs!O1 -> 3.25 | J7: =Table352[[#This Row],[Late Deduction]]+Table352[[#This Row],[Absence Days]]+Table352[[#This Row],[warning]] -> 17.25 | L7: 0 | M7: =Table352[[#This Row],[Total Cuts ]]*Table352[[#This Row],[Day Value]] -> 4025 | N7: =Table352[[#This Row],[Basic Salary]]-(Table352[[#This Row],[Total cuts Cash]]+Table352[[#This Row],[Loan]])+Table352[[#This Row],[extra from last month]] -> 2975 | O7: d
A8: c | B8: Marts | C8: Ahmed Nabil Hassan Ali Hassan | D8: 10000 | E8: 30 | F8: 0 | G8: =Table352[[#This Row],[Basic Salary]]/Table352[[#This Row],[Days]] -> 333.33333 | H8: 0 | I8: 0.25 | J8: =Table352[[#This Row],[Late Deduction]]+Table352[[#This Row],[Absence Days]]+Table352[[#This Row],[warning]] -> 0.25 | K8: 0 | L8: 0 | M8: =Table352[[#This Row],[Total Cuts ]]*Table352[[#This Row],[Day Value]] -> 83.333333 | N8: =Table352[[#This Row],[Basic Salary]]-(Table352[[#This Row],[Total cuts Cash]]+Table352[[#This Row],[Loan]])+Table352[[#This Row],[extra from last month]] -> 9916.6667 | P8: 2 days off annual
A9: c | B9: Marts | C9: Ahmed Nagib | D9: 3000 | E9: 30 | F9: 0 | G9: =Table352[[#This Row],[Basic Salary]]/Table352[[#This Row],[Days]] -> 100 | H9: 0 | I9: 0 | J9: =Table352[[#This Row],[Late Deduction]]+Table352[[#This Row],[Absence Days]]+Table352[[#This Row],[warning]] -> 0 | K9: 0 | L9: 0 | M9: =Table352[[#This Row],[Total Cuts ]]*Table352[[#This Row],[Day Value]] -> 0 | N9: =Table352[[#This Row],[Basic Salary]]-(Table352[[#This Row],[Total cuts Cash]]+Table352[[#This Row],[Loan]])+Table352[[#This Row],[extra from last month]] -> 3000
A10: b | B10: Marts | C10: Ali Wael Khedr Khamis | D10: 18000 | E10: 30 | F10: 0 | G10: =Table352[[#This Row],[Basic Salary]]/Table352[[#This Row],[Days]] -> 600 | H10: 0 | I10: =FPs!U1 -> 2.75 | J10: =Table352[[#This Row],[Late Deduction]]+Table352[[#This Row],[Absence Days]]+Table352[[#This Row],[warning]] -> 2.75 | K10: 0 | L10: 5000 | M10: =Table352[[#This Row],[Total Cuts ]]*Table352[[#This Row],[Day Value]] -> 1650 | N10: =Table352[[#This Row],[Basic Salary]]-(Table352[[#This Row],[Total cuts Cash]]+Table352[[#This Row],[Loan]])+Table352[[#This Row],[extra from last month]] -> 11350 | O10: d | P10: 2 days off annual
A11: c | B11: Marts | C11: Amal Ahmed Abbas Ebrahim | D11: 9000 | E11: 30 | F11: 22 | G11: =Table352[[#This Row],[Basic Salary]]/Table352[[#This Row],[Days]] -> 300 | I11: 0.25 | J11: =Table352[[#This Row],[Late Deduction]]+Table352[[#This Row],[Absence Days]]+Table352[[#This Row],[warning]] -> 22.25 | K11: 0 | L11: 0 | M11: =Table352[[#This Row],[Total Cuts ]]*Table352[[#This Row],[Day Value]] -> 6675 | N11: =Table352[[#This Row],[Basic Salary]]-(Table352[[#This Row],[Total cuts Cash]]+Table352[[#This Row],[Loan]])+Table352[[#This Row],[extra from last month]] -> 2325 | P11: starting date 23-6
A12: c | B12: Marts | C12: Amal Atef Mohamed Moshthe | D12: 7000 | E12: 30 | F12: 1 | G12: =Table352[[#This Row],[Basic Salary]]/Table352[[#This Row],[Days]] -> 233.33333 | H12: 0 | I12: 0.25 | J12: =Table352[[#This Row],[Late Deduction]]+Table352[[#This Row],[Absence Days]]+Table352[[#This Row],[warning]] -> 1.25 | K12: 0 | L12: 0 | M12: =Table352[[#This Row],[Total Cuts ]]*Table352[[#This Row],[Day Value]] -> 291.66667 | N12: =Table352[[#This Row],[Basic Salary]]-(Table352[[#This Row],[Total cuts Cash]]+Table352[[#This Row],[Loan]])+Table352[[#This Row],[extra from last month]] -> 6708.3333
